<?xml version="1.0" encoding="utf-8"?>
<!-- This URDF was automatically created by SolidWorks to URDF Exporter! Originally created by Stephen Brawner (brawner@gmail.com) 
     Commit Version: 1.6.0-1-g15f4949  Build Version: 1.6.7594.29634
     For more information, please see http://wiki.ros.org/sw_urdf_exporter -->
<robot
  name="proj_1_662">
  <link
    name="base_link">
    <inertial>
      <origin
        xyz="0.000124804484955887 0 -0.0635"
        rpy="0 0 0" />
      <mass
        value="10" />
      <inertia
        ixx="1.49453653108255"
        ixy="1.89942804167837E-16"
        ixz="4.19936742819075E-17"
        iyy="5.72560655658451"
        iyz="-2.9546767954756E-17"
        izz="7.04394364048466" />
    </inertial>
    <visual>
      <origin
        xyz="0 0 0"
        rpy="0 0 0" />
      <geometry>
        <mesh
          filename="package://proj_1_662/meshes/base_link.STL" />
      </geometry>
      <material
        name="">
        <color
          rgba="0.792156862745098 0.819607843137255 0.933333333333333 1" />
      </material>
    </visual>
    <collision>
      <origin
        xyz="0 0 0"
        rpy="0 0 0" />
      <geometry>
        <mesh
          filename="package://proj_1_662/meshes/base_link.STL" />
      </geometry>
    </collision>
  </link>
  <link
    name="right_wheel">
    <inertial>
      <origin
        xyz="0 0.0385215767634855 0"
        rpy="0 0 0" />
      <mass
        value="1" />
      <inertia
        ixx="0.256914732290794"
        ixy="-2.25616825207918E-18"
        ixz="2.50365449301499E-17"
        iyy="0.498212063009892"
        iyz="1.12449835322955E-18"
        izz="0.256914732290794" />
    </inertial>
    <visual>
      <origin
        xyz="0 0 0"
        rpy="0 0 0" />
      <geometry>
        <mesh
          filename="package://proj_1_662/meshes/right_wheel.STL" />
      </geometry>
      <material
        name="">
        <color
          rgba="0.792156862745098 0.819607843137255 0.933333333333333 1" />
      </material>
    </visual>
    <collision>
      <origin
        xyz="0 0 0"
        rpy="0 0 0" />
      <geometry>
        <mesh
          filename="package://proj_1_662/meshes/right_wheel.STL" />
      </geometry>
    </collision>
  </link>
  <joint
    name="right_wheel_joint"
    type="continuous">
    <origin
      xyz="-0.127 -0.3937 -0.0635"
      rpy="0 0 0" />
    <parent
      link="base_link" />
    <child
      link="right_wheel" />
    <axis
      xyz="0 1 0" />
  </joint>
  <link
    name="left_wheel">
    <inertial>
      <origin
        xyz="0 -0.0385215767634854 2.77555756156289E-17"
        rpy="0 0 0" />
      <mass
        value="1" />
      <inertia
        ixx="0.256914732290794"
        ixy="-1.58452137957618E-33"
        ixz="2.37838165062453E-38"
        iyy="0.498212063009892"
        iyz="-2.8980948269222E-34"
        izz="0.256914732290794" />
    </inertial>
    <visual>
      <origin
        xyz="0 0 0"
        rpy="0 0 0" />
      <geometry>
        <mesh
          filename="package://proj_1_662/meshes/left_wheel.STL" />
      </geometry>
      <material
        name="">
        <color
          rgba="0.792156862745098 0.819607843137255 0.933333333333333 1" />
      </material>
    </visual>
    <collision>
      <origin
        xyz="0 0 0"
        rpy="0 0 0" />
      <geometry>
        <mesh
          filename="package://proj_1_662/meshes/left_wheel.STL" />
      </geometry>
    </collision>
  </link>
  <joint
    name="left_wheel_joint"
    type="continuous">
    <origin
      xyz="-0.127 0.3937 -0.0635"
      rpy="0 0 0" />
    <parent
      link="base_link" />
    <child
      link="left_wheel" />
    <axis
      xyz="0 1 0" />
  </joint>
  <link
    name="castor_wheel">
    <inertial>
      <origin
        xyz="0 0 0"
        rpy="0 0 0" />
      <mass
        value="0.5" />
      <inertia
        ixx="0.013136314043539"
        ixy="-7.8692694421492E-35"
        ixz="-5.22024357439882E-51"
        iyy="0.013136314043539"
        iyz="0"
        izz="0.013136314043539" />
    </inertial>
    <visual>
      <origin
        xyz="0 0 0"
        rpy="0 0 0" />
      <geometry>
        <mesh
          filename="package://proj_1_662/meshes/castor_wheel.STL" />
      </geometry>
      <material
        name="">
        <color
          rgba="0.792156862745098 0.819607843137255 0.933333333333333 1" />
      </material>
    </visual>
    <collision>
      <origin
        xyz="0 0 0"
        rpy="0 0 0" />
      <geometry>
        <mesh
          filename="package://proj_1_662/meshes/castor_wheel.STL" />
      </geometry>
    </collision>
  </link>
  <joint
    name="castor_wheel_joint"
    type="fixed">
    <origin
      xyz="0.25081 -0.0018763 -0.22225"
      rpy="0 0 0" />
    <parent
      link="base_link" />
    <child
      link="castor_wheel" />
    <axis
      xyz="0 0 0" />
  </joint>
  <!-- Add dummy link and joint -->
  <link 
    name="dummy_link">
  </link>
  <joint name="dummy_joint" type="fixed">
    <parent link="dummy_link"/>
    <child link="base_link"/>
  </joint>
  <!-- gazebo controller -->
  <gazebo>
    <plugin name="differential_drive_controller" filename="libgazebo_ros_diff_drive.so">
    <alwaysOn>false</alwaysOn>
    <robotNamespace>/my_robot</robotNamespace>
    <commandTopic>/my_robot/mobile_base_controller/cmd_vel</commandTopic>
    <odometryTopic>/my_robot/mobile_base_controller/odom</odometryTopic>
    <rosDebugLevel>Debug</rosDebugLevel>
    <publishWheelTF>True</publishWheelTF>
    <publishWheelJointState>true</publishWheelJointState>
    <publishTf>1</publishTf>
    <legacyMode>false</legacyMode>
    <updateRate>20</updateRate>
    <leftJoint>left_wheel_joint</leftJoint>
    <rightJoint>right_wheel_joint</rightJoint>
    <wheelSeparation>0.1</wheelSeparation>
    <wheelDiameter>0.5</wheelDiameter>
    <wheelTorque>5</wheelTorque>
    <robotBaseFrame>base_link</robotBaseFrame>
    </plugin>
  </gazebo>

  <!-- add transmission -->
  <!-- <transmission name="left_wheel_transmission">
    <type>transmission_interface/SimpleTransmission</type>
    <joint name="left_wheel_joint">
      <hardwareInterface>hardware_interface/VelocityJointInterface</hardwareInterface>  
    </joint>
    <actuator name="left_wheel_actuator">
      <mechanicalReduction>7</mechanicalReduction>
      <hardwareInterface>VelocityJointInterface</hardwareInterface>
    </actuator>
  </transmission> -->
  <transmission name="right_wheel_joint_trans">
    <type>transmission_interface/SimpleTransmission</type>
    <joint name="right_wheel_joint"/>
    <actuator name="right_wheel_joint_motor">
      <hardwareInterface>VelocityJointInterface</hardwareInterface>
      <mechanicalReduction>7</mechanicalReduction>
    </actuator>
  </transmission>

  <transmission name="left_wheel_joint_trans">
    <type>transmission_interface/SimpleTransmission</type>
    <joint name="left_wheel_joint"/>
    <actuator name="left_wheel_joint_motor">
      <hardwareInterface>VelocityJointInterface</hardwareInterface>
      <mechanicalReduction>7</mechanicalReduction>
    </actuator>
  </transmission>
</robot>